<!-- Stanford Woofer Model

    The state space is populated with joints in the order that they are
    defined in this file.
-->
<mujoco model="cheetah">
  <compiler angle="radian" coordinate="local" inertiafromgeom="false"/>

  <default>
    <joint armature="woofer_armature" solimplimit="woofer_joint_solimp" solreflimit="woofer_joint_solref" stiffness="0"/>
    <geom conaffinity="0" condim="3" contype="1" friction="woofer_friction .1 .1" rgba="0.8 0.6 .4 1" solimp="woofer_geom_solimp" solref="woofer_geom_solref"/>
    <motor ctrllimited="true" forcelimited="true"/>
  </default>

	<option>
		<flag sensornoise="enable"/>
	</option>

	<sensor>
		<accelerometer name="accel" noise="woofer_accel_noise" site="imu_site"/>
		<gyro name="gyro" noise="woofer_gyro_noise" site="imu_site"/>

		<jointpos joint="fr_x" noise="woofer_encoder_noise"/>
		<jointpos joint="fr_y" noise="woofer_encoder_noise"/>
		<jointpos joint="fr_r" noise="woofer_encoder_noise"/>

		<jointpos joint="fl_x" noise="woofer_encoder_noise"/>
		<jointpos joint="fl_y" noise="woofer_encoder_noise"/>
		<jointpos joint="fl_r" noise="woofer_encoder_noise"/>

		<jointpos joint="br_x" noise="woofer_encoder_noise"/>
		<jointpos joint="br_y" noise="woofer_encoder_noise"/>
		<jointpos joint="br_r" noise="woofer_encoder_noise"/>

		<jointpos joint="bl_x" noise="woofer_encoder_noise"/>
		<jointpos joint="bl_y" noise="woofer_encoder_noise"/>
		<jointpos joint="bl_r" noise="woofer_encoder_noise"/>

		<jointvel joint="fr_x" noise="woofer_encoder_vel_noise"/>
		<jointvel joint="fr_y" noise="woofer_encoder_vel_noise"/>
		<jointvel joint="fr_r" noise="woofer_encoder_vel_noise"/>

		<jointvel joint="fl_x" noise="woofer_encoder_vel_noise"/>
		<jointvel joint="fl_y" noise="woofer_encoder_vel_noise"/>
		<jointvel joint="fl_r" noise="woofer_encoder_vel_noise"/>

		<jointvel joint="br_x" noise="woofer_encoder_vel_noise"/>
		<jointvel joint="br_y" noise="woofer_encoder_vel_noise"/>
		<jointvel joint="br_r" noise="woofer_encoder_vel_noise"/>

		<jointvel joint="bl_x" noise="woofer_encoder_vel_noise"/>
		<jointvel joint="bl_y" noise="woofer_encoder_vel_noise"/>
		<jointvel joint="bl_r" noise="woofer_encoder_vel_noise"/>
	</sensor>

  <size nstack="300000" nuser_geom="1"/>

	<!-- Took out gravity="0 0 -9.81" term-->
  <option timestep="woofer_timestep"/>
  <!-- <option gravity="0 0 0" timestep="woofer_timestep"/> -->
  <asset>
    <texture builtin="gradient" height="100" rgb1="1 1 1" rgb2="0 0 0" type="skybox" width="100"/>
    <texture builtin="flat" height="1278" mark="cross" markrgb="1 1 1" name="texgeom" random="0.01" rgb1="0.8 0.6 0.4" rgb2="0.8 0.6 0.4" type="cube" width="127"/>
    <texture builtin="checker" height="100" name="texplane" rgb1="0 0 0" rgb2="0.8 0.8 0.8" type="2d" width="100"/>
    <material name="MatPlane" reflectance="0.5" shininess="1" specular="1" texrepeat="60 60" texture="texplane"/>
    <material name="geom" texture="texgeom" texuniform="true"/>
  </asset>


  <worldbody>
    <light cutoff="100" diffuse="1 1 1" dir="-0 0 -1.3" directional="true" exponent="1" pos="0 0 1.3" specular=".1 .1 .1"/>
    <geom conaffinity="1" condim="3" material="MatPlane" name="floor" pos="0 0 0" rgba="0.8 0.9 0.8 1" size="40 40 40" type="plane"/>


    <body name="torso" pos="woofer_start_position">
      <camera name="track" mode="trackcom" pos="0 -2 0.3" xyaxes="1 0 0 0 0 1"/>
      <joint armature="0" axis="1 0 0" damping="0" limited="false" name="rootx" pos="0 0 0" stiffness="0" type="free"/>

			<inertial pos="0 0 0" mass="woofer_frame_mass" diaginertia="woofer_frame_inertia"/>
      <geom pos="0 0 0" name="torso" size="woofer_half_size" type="box"/>

			<site name="imu_site" pos="0 0 0" size=".01 .01 .01" type="box"/>

      <body name="fr_module" pos="woofer_leg_fb -woofer_leg_lr 0">
        <geom pos="0 0.05 0" name="fr_block" type="box" size="0.08 0.04 0.04" rgba="0.6 0.8 .4 1"/>

        <joint axis="1 0 0" name="fr_x" pos="0 0 0" limited="true" range="woofer_joint_range" type="hinge" damping="woofer_joint_damping"/>

				<inertial pos="0 0 0" mass="woofer_module_mass" fullinertia="woofer_module_inertia"/>

        <body name="fr" pos="0 0 0">
          <joint axis="0 1 0" name="fr_y" pos="0 0 0" limited="true" range="woofer_joint_range" type="hinge" damping="woofer_joint_damping"/>
          <joint axis="0 0 1" name="fr_r" pos = "0 0 0" limited="true" range="-0.18 0.18" type = "slide" damping="woofer_rad_damping"/>

					<inertial pos="0 0 0" mass="woofer_leg_mass" fullinertia="woofer_leg_inertia"/>

					<site name="fr_force_site" pos="woofer_force_geom" size=".01 .01 .01" type="box"/>
          <geom axisangle="0 1 0 0" name="fr" fromto="woofer_leg_geom" size="woofer_leg_radius" type="capsule" rgba = "1 0 0 0.5" density="50"/>
        </body>
      </body>

      <body name="fl_module" pos="woofer_leg_fb woofer_leg_lr 0">
        <geom pos = "0 -0.05 0" name="fl_block" type="box" size="0.08 0.04 0.04" rgba="0.6 0.8 .4 1"/>
        <joint axis="1 0 0" name="fl_x" pos="0 0 0" limited="true" range="woofer_joint_range" type="hinge" damping="woofer_joint_damping"/>

				<inertial pos="0 0 0" mass="woofer_module_mass" fullinertia="woofer_module_inertia"/>

        <body name="fl" pos="0 0 0">
          <joint axis="0 1 0" name="fl_y" pos="0 0 0" limited="true" range="woofer_joint_range" type="hinge" damping="woofer_joint_damping"/>
          <joint axis="0 0 1" name="fl_r" pos = "0 0 0" limited="true" range="-0.18 0.18" type = "slide" damping="woofer_rad_damping"/>

					<inertial pos="0 0 0" mass="woofer_leg_mass" fullinertia="woofer_leg_inertia"/>

					<site name="fl_force_site" pos="woofer_force_geom" size=".01 .01 .01" type="box"/>
					<geom axisangle="0 1 0 0" name="fl" fromto="woofer_leg_geom" size="woofer_leg_radius" type="capsule" rgba = "1 0 0 0.5" density="50"/>
        </body>
      </body>

      <body name="br_module" pos="-woofer_leg_fb -woofer_leg_lr 0">
        <geom pos = "0 0.05 0" name="br_block" type="box" size="0.08 0.04 0.04" rgba="0.6 0.8 .4 1"/>
        <joint axis="1 0 0" name="br_x" pos="0 0 0" limited="true" range="woofer_joint_range" type="hinge" damping="woofer_joint_damping"/>

				<inertial pos="0 0 0" mass="woofer_module_mass" fullinertia="woofer_module_inertia"/>

        <body name="br" pos="0 0 0">
          <joint axis="0 1 0" name="br_y" pos="0 0 0" limited="true" range="woofer_joint_range" type="hinge" damping="woofer_joint_damping"/>
          <joint axis="0 0 1" name="br_r" pos = "0 0 0" limited="true" range="-0.18 0.18" type = "slide" damping="woofer_rad_damping"/>

					<inertial pos="0 0 0" mass="woofer_leg_mass" fullinertia="woofer_leg_inertia"/>

					<site name="br_force_site" pos="woofer_force_geom" size=".01 .01 .01" type="box"/>
					<geom axisangle="0 1 0 0" name="br" fromto="woofer_leg_geom" size="woofer_leg_radius" type="capsule" rgba = "1 0 0 0.5" density="50"/>
        </body>
      </body>

      <body name="bl_module" pos="-woofer_leg_fb woofer_leg_lr 0">
        <geom pos = "0 -0.05 0" name="bl_block" type="box" size="0.08 0.04 0.04" rgba="0.6 0.8 .4 1"/>
        <joint axis="1 0 0" name="bl_x" pos="0 0 0" limited="true" range="woofer_joint_range" type="hinge" damping="woofer_joint_damping"/>

				<inertial pos="0 0 0" mass="woofer_module_mass" fullinertia="woofer_module_inertia"/>

        <body name="bl" pos="0 0 0">
          <joint axis="0 1 0" name="bl_y" pos="0 0 0" limited="true" range="woofer_joint_range" type="hinge" damping="woofer_joint_damping"/>
          <joint axis="0 0 1" name="bl_r" pos = "0 0 0" limited="true" range="woofer_ext_range" type = "slide" damping="woofer_rad_damping"/>

					<inertial pos="0 0 0" mass="woofer_leg_mass" fullinertia="woofer_leg_inertia"/>

					<site name="bl_force_site" pos="woofer_force_geom" size=".01 .01 .01" type="box"/>
					<geom axisangle="0 1 0 0" name="bl" fromto="woofer_leg_geom" size="woofer_leg_radius" type="capsule" rgba = "1 0 0 0.5" density="50"/>
        </body>
      </body>


    </body>
  </worldbody>



  <actuator>
    <motor gear="1" joint="fr_x" name="fr_x" forcerange="woofer_joint_force_range" ctrlrange="woofer_joint_force_range"/>
    <motor gear="1" joint="fr_y" name="fr_y" forcerange="woofer_joint_force_range" ctrlrange="woofer_joint_force_range"/>
    <motor gear="1" joint="fr_r" name="fr_r" forcerange="woofer_ext_force_range" ctrlrange="woofer_ext_force_range"/>

    <motor gear="1" joint="fl_x" name="fl_x" forcerange="woofer_joint_force_range" ctrlrange="woofer_joint_force_range"/>
    <motor gear="1" joint="fl_y" name="fl_y" forcerange="woofer_joint_force_range" ctrlrange="woofer_joint_force_range"/>
    <motor gear="1" joint="fl_r" name="fl_r" forcerange="woofer_ext_force_range" ctrlrange="woofer_ext_force_range"/>

    <motor gear="1" joint="br_x" name="br_x" forcerange="woofer_joint_force_range" ctrlrange="woofer_joint_force_range"/>
    <motor gear="1" joint="br_y" name="br_y" forcerange="woofer_joint_force_range" ctrlrange="woofer_joint_force_range"/>
    <motor gear="1" joint="br_r" name="br_r" forcerange="woofer_ext_force_range" ctrlrange="woofer_ext_force_range"/>

    <motor gear="1" joint="bl_x" name="bl_x" forcerange="woofer_joint_force_range" ctrlrange="woofer_joint_force_range"/>
    <motor gear="1" joint="bl_y" name="bl_y" forcerange="woofer_joint_force_range" ctrlrange="woofer_joint_force_range"/>
    <motor gear="1" joint="bl_r" name="bl_r" forcerange="woofer_ext_force_range" ctrlrange="woofer_ext_force_range"/>
  </actuator>
</mujoco>
